<?xml version="1.0" encoding="utf-8"?>
<!-- This URDF was automatically created by SolidWorks to URDF Exporter! Originally created by Stephen Brawner (brawner@gmail.com) 
     Commit Version: 1.6.0-4-g7f85cfe  Build Version: 1.6.7995.38578
     For more information, please see http://wiki.ros.org/sw_urdf_exporter -->
<robot
  name="roboticarm">
  <link
    name="robot_base">
    <inertial>
      <origin
        xyz="0.062053 0.000214 0.026334"
        rpy="0 0 0" />
      <mass
        value="5" />
      <inertia
        ixx="0.0022893"
        ixy="-1.8956E-07"
        ixz="0.00091472"
        iyy="0.011178"
        iyz="9.2797E-08"
        izz="0.012678" />
    </inertial>
    <visual>
      <origin
        xyz="0 0 0"
        rpy="0 0 0" />
      <geometry>
        <mesh
          filename="package://roboticarm/meshes/robot_base.STL" />
      </geometry>
      <material
        name="">
        <color
          rgba="0.79216 0.81961 0.93333 1" />
      </material>
    </visual>
    <collision>
      <origin
        xyz="0 0 0"
        rpy="0 0 0" />
      <geometry>
        <mesh
          filename="package://roboticarm/meshes/robot_base.STL" />
      </geometry>
    </collision>
  </link>
  <link
    name="link_1">
    <inertial>
      <origin
        xyz="-0.00025379 5.5758E-06 0.0071497"
        rpy="0 0 0" />
      <mass
        value="1" />
      <inertia
        ixx="0.00012711"
        ixy="-9.2677E-08"
        ixz="-1.6493E-13"
        iyy="0.0001284"
        iyz="-1.789E-07"
        izz="0.00025256" />
    </inertial>
    <visual>
      <origin
        xyz="0 0 0"
        rpy="0 0 0" />
      <geometry>
        <mesh
          filename="package://roboticarm/meshes/link_1.STL" />
      </geometry>
      <material
        name="">
        <color
          rgba="0.79216 0.81961 0.93333 1" />
      </material>
    </visual>
    <collision>
      <origin
        xyz="0 0 0"
        rpy="0 0 0" />
      <geometry>
        <mesh
          filename="package://roboticarm/meshes/link_1.STL" />
      </geometry>
    </collision>
  </link>
  <joint
    name="joint_1"
    type="revolute">
    <origin
      xyz="0 0 0.0947"
      rpy="0 0 1.5708" />
    <parent
      link="robot_base" />
    <child
      link="link_1" />
    <axis
      xyz="0 0 -1" />
    <limit
      lower="-0.785"
      upper="0.785"
      effort="0"
      velocity="0" />
  </joint>
  <link
    name="link_2">
    <inertial>
      <origin
        xyz="-0.0058402 0.025415 0.09891"
        rpy="0 0 0" />
      <mass
        value="1" />
      <inertia
        ixx="5.6134E-05"
        ixy="-1.26E-07"
        ixz="-1.2372E-06"
        iyy="3.5146E-05"
        iyz="1.4388E-07"
        izz="3.9106E-05" />
    </inertial>
    <visual>
      <origin
        xyz="0 0 0"
        rpy="0 0 0" />
      <geometry>
        <mesh
          filename="package://roboticarm/meshes/link_2.STL" />
      </geometry>
      <material
        name="">
        <color
          rgba="0.79216 0.81961 0.93333 1" />
      </material>
    </visual>
    <collision>
      <origin
        xyz="0 0 0"
        rpy="0 0 0" />
      <geometry>
        <mesh
          filename="package://roboticarm/meshes/link_2.STL" />
      </geometry>
    </collision>
  </link>
  <joint
    name="joint_2"
    type="revolute">
    <origin
      xyz="-0.011637 -0.026701 0.019"
      rpy="0 0 0" />
    <parent
      link="link_1" />
    <child
      link="link_2" />
    <axis
      xyz="0 1 0" />
    <limit
      lower="-0.785"
      upper="0.785"
      effort="0"
      velocity="0" />
  </joint>
  <link
    name="link_3">
    <inertial>
      <origin
        xyz="-0.0023903 -0.046666 -0.0060841"
        rpy="0 0 0" />
      <mass
        value="1" />
      <inertia
        ixx="5.7391E-06"
        ixy="-1.5165E-07"
        ixz="2.9807E-09"
        iyy="3.566E-06"
        iyz="-1.1049E-10"
        izz="7.9979E-06" />
    </inertial>
    <visual>
      <origin
        xyz="0 0 0"
        rpy="0 0 0" />
      <geometry>
        <mesh
          filename="package://roboticarm/meshes/link_3.STL" />
      </geometry>
      <material
        name="">
        <color
          rgba="0.79216 0.81961 0.93333 1" />
      </material>
    </visual>
    <collision>
      <origin
        xyz="0 0 0"
        rpy="0 0 0" />
      <geometry>
        <mesh
          filename="package://roboticarm/meshes/link_3.STL" />
      </geometry>
    </collision>
  </link>
  <joint
    name="joint_3"
    type="revolute">
    <origin
      xyz="-0.076851 0.03547 0.12006"
      rpy="0.23129 0 -1.5328" />
    <parent
      link="link_2" />
    <child
      link="link_3" />
    <axis
      xyz="0.036969 0.99932 0" />
    <limit
      lower="-0.785"
      upper="0.785"
      effort="0"
      velocity="0" />
  </joint>
</robot>